Workbook

Sheet Resum
A1: Espai x esquema. | H1: Espai x Taules
A3: Es pot eliminar | B3: Suma de GB | H3: Es pot eliminar | I3: Suma de GBBytes
A4: ?? | B4: 532.52 | H4: ?? | I4: 21.717773
A5: No | B5: 5642.52 | H5: No | I5: 1890.374
A6: Grup1 | B6: 135.15 | H6: Sí | I6: 86.021484
A7: Sí | B7: 117.21 | H7: (en blanc) | I7: 54.072266
A8: Sí, però | B8: 17.94 | H8: Total general | I8: 2052.1855
A9: Total general | B9: 6310.19
A16: Es pot eliminar? | B16: (Múltiples elements) | H16: Es pot eliminar? | I16: Sí
A18: Etiquetes de fila | B18: Suma de GB | H18: Etiquetes de fila | I18: Suma de GBBytes
A19: Andrea Cánovas | B19: 67.88 | H19: ?? | I19: 6.9833984
A20: E13_AUP | B20: 0 | H20: E13_IDA | I20: 6.9833984
A21: E13_BAG | B21: 0.28 | H21: Andrea Cánovas | I21: 45.837891
A22: E13_PAV | B22: 67.44 | H22: E13_A4S | I22: 0.1953125
A23: E13_PPQPIS | B23: 0.16 | H23: E13_BAE | I23: 34.798828
A24: Daniel Moreiras | B24: 0.26 | H24: E13_GSA_ACR | I24: 0.171875
A25: E13_PREMISCAT | B25: 0 | H25: E13_OVT_PUBLI | I25: 1.828125
A26: E13_RESERVA_SALES | B26: 0.26 | H26: E13_PAV | I26: 1.4199219
A27: GEPSE | B27: 0 | H27: E13_RALC | I27: 0.296875
A28: Jordi Sala | B28: 61.22 | H28: E13_RTA | I28: 4.6425781
A29: E13_ADPD | B29: 0.07 | H29: E13_RTT | I29: 2.484375
A30: E13_AJUTS | B30: 0 | H30: Jordi Sala | I30: 6.0292969
... A43: E13_LLENGUES | B43: 0.08 | H43: Total general | I43: 86.021484
A44: E13_LLICENCIES | B44: 0.18
A45: E13_OFERTA_BCK | B45: 32.25
A46: E13_OPO | B46: 0.02
A47: E13_OPOSPAS | B47: 0
A48: E13_PUB_RESULTATS | B48: 0.02
A49: (en blanc) | B49: 0.44
A50: AM10_38136279W | B50: 0.01
A51: E13_APE_1011 | B51: 0.04
A52: E13_APE_1112 | B52: 0.03
A53: E13_APE_1213 | B53: 0.02
A54: E13_CARTERA | B54: 0.34
A55: JMARQUE4 | B55: 0
... A58: Total general | B58: 135.15

Sheet Espai x esquema
A1: Owner | B1: table | C1: MB | D1: GB | E1: Es pot eliminar? | F1: Lot | G1: - | H1: Observacions | I1: Aplicació | J1: GS | K1: Estat
A2: AD | B2: total_owner | C2: 6917.81 | D2: 6.76 | E2: No | F2: AM10
A3: ADMCTRL | B3: total_owner | C3: 6940.75 | D3: 6.78 | E3: No | F3: AM10
A4: ADMINXTEC | B4: total_owner | C4: 955.44 | D4: 0.93 | E4: No | F4: AM10
A5: ADMXTEC | B5: total_owner | C5: 84433.38 | D5: 82.45 | E5: No | F5: AM10
A6: FLOWS_FILES | B6: total_owner | C6: 263449 | D6: 257.27 | E6: ?? | H6: XMC:Identificar dependències, jobs, sh, ultim accés user, útimes operacions DML/DDL. Revocar permisos abans d'eliminar
A7: AIDA | B7: total_owner | C7: 0.81 | D7: 0 | E7: No | F7: AM10
A8: AM10_38136279W | B8: total_owner | C8: 13.06 | D8: 0.01 | E8: Sí | F8: AM10
A9: APEX_200200 | B9: total_owner | C9: 8376.19 | D9: 8.18 | E9: No | F9: N/A
A10: APEX_SSO | B10: total_owner | C10: 0.63 | D10: 0 | E10: ?? | F10: AM10 | H10: XMC:Identificar dependències, jobs, sh, ultim accés user, útimes operacions DML/DDL. Revocar permisos abans d'eliminar
A11: E13_GICARSM | B11: total_owner | C11: 53826.13 | D11: 52.56 | E11: ?? | H11: XMC:Identificar dependències, jobs, sh, ultim accés user, útimes operacions DML/DDL. Revocar permisos abans d'eliminar | K11: Es pot eliminar
A12: AUDSYS | B12: total_owner | C12: 155463.63 | D12: 151.82 | E12: no | H12: XMC:Identificar dependències i continuar anàlisi
A13: AVA | B13: total_owner | C13: 609.94 | D13: 0.6 | E13: No | F13: AM10 | I13: AVA | J13: Andrea Cánovas
A14: BFGH_INT_LOCAL | B14: total_owner | C14: 217.38 | D14: 0.21 | E14: No | F14: AM11 | H14: Esquema que s'utilitza per connectar a DMA's, beques i per accés a dades del RALC d'ESFERA
A15: E13_ESPINA_BD | B15: total_owner | C15: 6056.13 | D15: 5.91 | E15: ?? | H15: XMC: Encara la fa servir DMA SAGA AM11
A16: CLIC | B16: total_owner | C16: 152.88 | D16: 0.15 | E16: No | F16: AM10 | H16: XMC:Per què no? No es va migrar??
A17: DBSFWUSER | B17: total_owner | C17: 0.38 | D17: 0 | E17: no | H17: XMC:Identificar dependències i continuar anàlisi | K17: No surt cap info
A18: VFS_NICE_264 | B18: total_owner | C18: 5684.69 | D18: 5.55 | E18: ?? | H18: XMC:Identificar dependències, jobs, sh, ultim accés user, útimes operacions DML/DDL. Revocar permisos abans d'eliminar
A19: XT20_LIFERAY | B19: total_owner | C19: 2835.38 | D19: 2.77 | E19: ?? | H19: XMC:Identificar dependències, jobs, sh, ultim accés user, útimes operacions DML/DDL. Revocar permisos abans d'eliminar
A20: E13_A4S | B20: total_owner | C20: 24148.88 | D20: 23.58 | E20: No | F20: AM10
A21: E13_A6P | B21: total_owner | C21: 25327.19 | D21: 24.73 | E21: No | F21: AM10
A22: E13_AAC_PREINS | B22: total_owner | C22: 31432.25 | D22: 30.7 | E22: Sí | F22: AM10 | H22: Pendent decisió ATIC
A23: E13_ACO | B23: total_owner | C23: 115.38 | D23: 0.11 | E23: No | F23: AM10
A24: E13_ADPD | B24: total_owner | C24: 74.5 | D24: 0.07 | E24: Sí, però | F24: AM05 | H24: Es podria historificar i treure d'E13BD, aplicació tancada i obsoleta | I24: ADPD | J24: Jordi Sala
A25: E13_AFD | B25: total_owner | C25: 22.31 | D25: 0.02 | E25: ?? | F25: AM05 | H25: DMM: Es troba de baixa a l'inventari d'app | I25: AFD | J25: Jordi Sala
A26: E13_AGAI | B26: total_owner | C26: 260 | D26: 0.25 | E26: No | F26: AM05
A27: E13_AGD | B27: total_owner | C27: 53188.63 | D27: 51.94 | E27: No | F27: AM10
A28: E13_AGIN | B28: total_owner | C28: 112386.25 | D28: 109.75 | E28: No | F28: AM15
A29: E13_AJUTS | B29: total_owner | C29: 4.19 | D29: 0 | E29: Sí, però | F29: AM05 | H29: Es podria historificar i treure d'E13BD, aplicació tancada i obsoleta | I29: GSD_AJUTS | J29: Jordi Sala
A30: SIGMA | B30: total_owner | C30: 2318.13 | D30: 2.26 | E30: ?? | H30: XMC:Identificar dependències, jobs, sh, ultim accés user, útimes operacions DML/DDL. Revocar permisos abans d'eliminar
A31: E13_APBLOE | B31: total_owner | C31: 1087.19 | D31: 1.06 | E31: ?? | F31: AM11 | H31: DMM: Es troba de baixa a l'inventari d'app | I31: APBLOE | J31: Oscar Méndez
A32: E13_VAD_TSYSTEM | B32: total_owner | C32: 1792.5 | D32: 1.75 | E32: ?? | H32: XMC:Identificar dependències, jobs, sh, ultim accés user, útimes operacions DML/DDL. Revocar permisos abans d'eliminar | K32: Revisar 3.2 E13_AWA
A33: E13_APE | B33: total_owner | C33: 415.06 | D33: 0.41 | E33: No | F33: AM05
A34: E13_APE_1011 | B34: total_owner | C34: 38.06 | D34: 0.04 | E34: Sí, però | F34: AM05 | H34: Són unes campanyes antigues, es podrien historificar i treure d'E13BD
A35: E13_APE_1112 | B35: total_owner | C35: 28.31 | D35: 0.03 | E35: Sí, però | F35: AM05 | H35: Són unes campanyes antigues, es podrien historificar
A36: E13_APE_1213 | B36: total_owner | C36: 23 | D36: 0.02 | E36: Sí, però | F36: AM05 | H36: Són unes campanyes antigues, es podrien historificar
A37: E13_ASAELE | B37: total_owner | C37: 242.69 | D37: 0.24 | E37: No | F37: AM10 | H37: No es pot borrar
A38: E13_ASD | B38: total_owner | C38: 18.94 | D38: 0.02 | E38: Sí, però | F38: AM05 | H38: Es podria historificar i treure d'E13BD, aplicació tancada i obsoleta | I38: ASD | J38: Jordi Sala
A39: E13_ASD_PUBLI | B39: total_owner | C39: 1.5 | D39: 0 | E39: Sí, però | F39: AM05 | H39: Es podria historificar i treure d'E13BD, aplicació tancada i obsoleta | I39: ASD_PUBLI | J39: Jordi Sala
A40: GGAA | B40: total_owner | C40: 1741.44 | D40: 1.7 | E40: ?? | H40: XMC:Identificar dependències, jobs, sh, ultim accés user, útimes operacions DML/DDL. Revocar permisos abans d'eliminar
...

Sheet Hoja1
A1: OR UPPER(text) LIKE '% | B1: ADSL | C1: .%' | D1: =CONCATENATE(A1,TRIM(B1),C1) -> OR UPPER(text) LIKE '%ADSL.%'
A2: OR UPPER(text) LIKE '% | B2: AM10_38136279W | C2: .%' | D2: =CONCATENATE(A2,TRIM(B2),C2) -> OR UPPER(text) LIKE '%AM10_38136279W.%'
A3: OR UPPER(text) LIKE '% | B3: APEX_SSO | C3: .%' | D3: =CONCATENATE(A3,TRIM(B3),C3) -> OR UPPER(text) LIKE '%APEX_SSO.%'
A4: OR UPPER(text) LIKE '% | B4: AUDITORI | C4: .%' | D4: =CONCATENATE(A4,TRIM(B4),C4) -> OR UPPER(text) LIKE '%AUDITORI.%'
A5: OR UPPER(text) LIKE '% | B5: BIPUBSCHED | C5: .%' | D5: =CONCATENATE(A5,TRIM(B5),C5) -> OR UPPER(text) LIKE '%BIPUBSCHED.%'
A6: OR UPPER(text) LIKE '% | B6: DIRCENT | C6: .%' | D6: =CONCATENATE(A6,TRIM(B6),C6) -> OR UPPER(text) LIKE '%DIRCENT.%'
A7: OR UPPER(text) LIKE '% | B7: DUPLIXTEC | C7: .%' | D7: =CONCATENATE(A7,TRIM(B7),C7) -> OR UPPER(text) LIKE '%DUPLIXTEC.%'
A8: OR UPPER(text) LIKE '% | B8: E13_ADPD | C8: .%' | D8: =CONCATENATE(A8,TRIM(B8),C8) -> OR UPPER(text) LIKE '%E13_ADPD.%'
A9: OR UPPER(text) LIKE '% | B9: E13_AFD | C9: .%' | D9: =CONCATENATE(A9,TRIM(B9),C9) -> OR UPPER(text) LIKE '%E13_AFD.%'
A10: OR UPPER(text) LIKE '% | B10: E13_AJUTS | C10: .%' | D10: =CONCATENATE(A10,TRIM(B10),C10) -> OR UPPER(text) LIKE '%E13_AJUTS.%'
A11: OR UPPER(text) LIKE '% | B11: E13_APACTIU | C11: .%' | D11: =CONCATENATE(A11,TRIM(B11),C11) -> OR UPPER(text) LIKE '%E13_APACTIU.%'
A12: OR UPPER(text) LIKE '% | B12: E13_APBLOE | C12: .%' | D12: =CONCATENATE(A12,TRIM(B12),C12) -> OR UPPER(text) LIKE '%E13_APBLOE.%'
... A109: OR UPPER(text) LIKE '% | B109: XTEC_ALTES | C109: .%' | D109: =CONCATENATE(A109,TRIM(B109),C109) -> OR UPPER(text) LIKE '%XTEC_ALTES.%'

Sheet Espai x taules
A1: OWNER | B1: TABLE | C1: MBYTES | D1: GBBytes | E1: Es pot eliminar? | F1: Lot | G1: Política esborrat/conservació? | H1: Observacions | I1: Aplicació | J1: GS | K1: Pertany esquema obsolet
A2: E13_CWS | B2: OSB_TRACES_COMUNES | C2: 468851 | D2: =new_212__3[[#This Row],[MBYTES]]/1024 -> 457.8623 | E2: No | F2: AM10 | H2: Taula amb els registres de log de l'OSB a partir del 2021 | K2: {=IF(_xlfn.XLOOKUP(TRIM(A2),TRIM('Espai x esquema'!$A:$A),'Espai x esquema'!$E:$E,"",0)="Sí, però", "Sí", _xlfn.XLOOKUP(TRIM(A2),TRIM('Espai x esquema'!$A:$A),'Espai x esquema'!$E:$E,"",0))} -> No
A3: E13_AWA | B3: UTILS_TB_LOG | C3: 301223 | D3: =new_212__3[[#This Row],[MBYTES]]/1024 -> 294.16309 | E3: No | F3: AM10 | G3: Cal conservar, es manté el LOG de 1 mes | K3: {=IF(_xlfn.XLOOKUP(TRIM(A3),TRIM('Espai x esquema'!$A:$A),'Espai x esquema'!$E:$E,"",0)="Sí, però", "Sí", _xlfn.XLOOKUP(TRIM(A3),TRIM('Espai x esquema'!$A:$A),'Espai x esquema'!$E:$E,"",0))} -> No
A4: E13_CWS | B4: OSB_TRACES_COMUNES_BCK | C4: 197348 | D4: =new_212__3[[#This Row],[MBYTES]]/1024 -> 192.72266 | E4: No | F4: AM10 | H4: Taula amb els registres de log de l'OSB fins al 2021 | K4: {=IF(_xlfn.XLOOKUP(TRIM(A4),TRIM('Espai x esquema'!$A:$A),'Espai x esquema'!$E:$E,"",0)="Sí, però", "Sí", _xlfn.XLOOKUP(TRIM(A4),TRIM('Espai x esquema'!$A:$A),'Espai x esquema'!$E:$E,"",0))} -> No
A5: IDI | B5: UTILS_TB_HST_LOG | C5: 121019 | D5: =new_212__3[[#This Row],[MBYTES]]/1024 -> 118.18262 | E5: No | F5: AM10 | G5: Cal conservar, es manté el LOG de 2 anys | K5: {=IF(_xlfn.XLOOKUP(TRIM(A5),TRIM('Espai x esquema'!$A:$A),'Espai x esquema'!$E:$E,"",0)="Sí, però", "Sí", _xlfn.XLOOKUP(TRIM(A5),TRIM('Espai x esquema'!$A:$A),'Espai x esquema'!$E:$E,"",0))} -> No
A6: GEDAC | B6: PROCES_GEDAC_DETALL | C6: 55825 | D6: =new_212__3[[#This Row],[MBYTES]]/1024 -> 54.516602 | E6: No | F6: AM10 | G6: No existeix política d'esborrat. | K6: {=IF(_xlfn.XLOOKUP(TRIM(A6),TRIM('Espai x esquema'!$A:$A),'Espai x esquema'!$E:$E,"",0)="Sí, però", "Sí", _xlfn.XLOOKUP(TRIM(A6),TRIM('Espai x esquema'!$A:$A),'Espai x esquema'!$E:$E,"",0))} -> No
A7: ADMXTEC | B7: UTILS_TB_HST_LOG | C7: 51330 | D7: =new_212__3[[#This Row],[MBYTES]]/1024 -> 50.126953 | E7: No | F7: AM10 | G7: Cal conservar, es manté el LOG de 6 mesos | K7: {=IF(_xlfn.XLOOKUP(TRIM(A7),TRIM('Espai x esquema'!$A:$A),'Espai x esquema'!$E:$E,"",0)="Sí, però", "Sí", _xlfn.XLOOKUP(TRIM(A7),TRIM('Espai x esquema'!$A:$A),'Espai x esquema'!$E:$E,"",0))} -> No
A8: GAFADM | B8: T_LOG_PERSONA | C8: 50780 | D8: 49.589844 | E8: No | F8: AM05 | G8: No en té | K8: {=IF(_xlfn.XLOOKUP(TRIM(A8),TRIM('Espai x esquema'!$A:$A),'Espai x esquema'!$E:$E,"",0)="Sí, però", "Sí", _xlfn.XLOOKUP(TRIM(A8),TRIM('Espai x esquema'!$A:$A),'Espai x esquema'!$E:$E,"",0))} -> No
A9: E13_CWS | B9: UTILS_TB_HST_LOG | C9: 43550 | D9: =new_212__3[[#This Row],[MBYTES]]/1024 -> 42.529297 | E9: No | F9: AM10 | G9: Cal conservar, es manté el LOG de 2 anys | K9: {=IF(_xlfn.XLOOKUP(TRIM(A9),TRIM('Espai x esquema'!$A:$A),'Espai x esquema'!$E:$E,"",0)="Sí, però", "Sí", _xlfn.XLOOKUP(TRIM(A9),TRIM('Espai x esquema'!$A:$A),'Espai x esquema'!$E:$E,"",0))} -> No
A10: IDI | B10: UTILS_TB_LOG | C10: 40938 | D10: =new_212__3[[#This Row],[MBYTES]]/1024 -> 39.978516 | E10: No | F10: AM10 | G10: Cal conservar, es manté el LOG de 6 mesos | K10: {=IF(_xlfn.XLOOKUP(TRIM(A10),TRIM('Espai x esquema'!$A:$A),'Espai x esquema'!$E:$E,"",0)="Sí, però", "Sí", _xlfn.XLOOKUP(TRIM(A10),TRIM('Espai x esquema'!$A:$A),'Espai x esquema'!$E:$E,"",0))} -> No
A11: E13_GICARSM | B11: SMACCESSLOG4 | C11: 39562 | D11: =new_212__3[[#This Row],[MBYTES]]/1024 -> 38.634766 | K11: {=IF(_xlfn.XLOOKUP(TRIM(A11),TRIM('Espai x esquema'!$A:$A),'Espai x esquema'!$E:$E,"",0)="Sí, però", "Sí", _xlfn.XLOOKUP(TRIM(A11),TRIM('Espai x esquema'!$A:$A),'Espai x esquema'!$E:$E,"",0))} -> ??
A12: E13_SSO_SM | B12: UTILS_TB_LOG | C12: 38519 | D12: =new_212__3[[#This Row],[MBYTES]]/1024 -> 37.616211 | E12: No | F12: AM10 | G12: No exisitex política d'esborrat | K12: {=IF(_xlfn.XLOOKUP(TRIM(A12),TRIM('Espai x esquema'!$A:$A),'Espai x esquema'!$E:$E,"",0)="Sí, però", "Sí", _xlfn.XLOOKUP(TRIM(A12),TRIM('Espai x esquema'!$A:$A),'Espai x esquema'!$E:$E,"",0))} -> No
A13: E13_OVT_PUBLI | B13: OVT_PUBLITB_AP_RESULTATS | C13: 27168 | D13: =new_212__3[[#This Row],[MBYTES]]/1024 -> 26.53125 | E13: No | F13: AM10 | G13: Taula d'aplicació. No aplica | K13: {=IF(_xlfn.XLOOKUP(TRIM(A13),TRIM('Espai x esquema'!$A:$A),'Espai x esquema'!$E:$E,"",0)="Sí, però", "Sí", _xlfn.XLOOKUP(TRIM(A13),TRIM('Espai x esquema'!$A:$A),'Espai x esquema'!$E:$E,"",0))} -> No
A14: E13_CWS | B14: UTILS_TB_LOG | C14: 25430 | D14: =new_212__3[[#This Row],[MBYTES]]/1024 -> 24.833984 | E14: No | F14: AM10 | G14: Cal conservar, es manté el LOG de 6 mesos | K14: {=IF(_xlfn.XLOOKUP(TRIM(A14),TRIM('Espai x esquema'!$A:$A),'Espai x esquema'!$E:$E,"",0)="Sí, però", "Sí", _xlfn.XLOOKUP(TRIM(A14),TRIM('Espai x esquema'!$A:$A),'Espai x esquema'!$E:$E,"",0))} -> No
A15: GEDAC | B15: LOG_SOLICITUDS_HISTORIC | C15: 23106 | D15: =new_212__3[[#This Row],[MBYTES]]/1024 -> 22.564453 | E15: No | F15: AM10 | G15: Taula destinària de l'esborrat de LOG_SOLICITUDS | K15: {=IF(_xlfn.XLOOKUP(TRIM(A15),TRIM('Espai x esquema'!$A:$A),'Espai x esquema'!$E:$E,"",0)="Sí, però", "Sí", _xlfn.XLOOKUP(TRIM(A15),TRIM('Espai x esquema'!$A:$A),'Espai x esquema'!$E:$E,"",0))} -> No
A16: E13_RALC | B16: UTILS_TB_HST_LOG | C16: 20848 | D16: =new_212__3[[#This Row],[MBYTES]]/1024 -> 20.359375 | E16: No | F16: AM10 | G16: Cal conservar, es manté el LOG de 2 anys | K16: {=IF(_xlfn.XLOOKUP(TRIM(A16),TRIM('Espai x esquema'!$A:$A),'Espai x esquema'!$E:$E,"",0)="Sí, però", "Sí", _xlfn.XLOOKUP(TRIM(A16),TRIM('Espai x esquema'!$A:$A),'Espai x esquema'!$E:$E,"",0))} -> No
A17: E13_SML | B17: TWSC_MAILS | C17: 17503 | D17: =new_212__3[[#This Row],[MBYTES]]/1024 -> 17.092773 | E17: No | F17: AM10 | G17: Cal conservar, es manté el LOG de 1 mes | K17: {=IF(_xlfn.XLOOKUP(TRIM(A17),TRIM('Espai x esquema'!$A:$A),'Espai x esquema'!$E:$E,"",0)="Sí, però", "Sí", _xlfn.XLOOKUP(TRIM(A17),TRIM('Espai x esquema'!$A:$A),'Espai x esquema'!$E:$E,"",0))} -> No
A18: PAEC | B18: UTILS_TB_LOG | C18: 17205 | D18: =new_212__3[[#This Row],[MBYTES]]/1024 -> 16.801758 | E18: No | F18: AM10 | K18: {=IF(_xlfn.XLOOKUP(TRIM(A18),TRIM('Espai x esquema'!$A:$A),'Espai x esquema'!$E:$E,"",0)="Sí, però", "Sí", _xlfn.XLOOKUP(TRIM(A18),TRIM('Espai x esquema'!$A:$A),'Espai x esquema'!$E:$E,"",0))} -> No
A19: E13_MSG | B19: MSG_TB_PETICIO_DET | C19: 16314 | D19: =new_212__3[[#This Row],[MBYTES]]/1024 -> 15.931641 | E19: No | F19: AM10 | G19: No exisitex política d'esborrat | K19: {=IF(_xlfn.XLOOKUP(TRIM(A19),TRIM('Espai x esquema'!$A:$A),'Espai x esquema'!$E:$E,"",0)="Sí, però", "Sí", _xlfn.XLOOKUP(TRIM(A19),TRIM('Espai x esquema'!$A:$A),'Espai x esquema'!$E:$E,"",0))} -> No
A20: E13_VAD | B20: VADTB_LOG | C20: 15808 | D20: =new_212__3[[#This Row],[MBYTES]]/1024 -> 15.4375 | F20: AM10 | K20: {=IF(_xlfn.XLOOKUP(TRIM(A20),TRIM('Espai x esquema'!$A:$A),'Espai x esquema'!$E:$E,"",0)="Sí, però", "Sí", _xlfn.XLOOKUP(TRIM(A20),TRIM('Espai x esquema'!$A:$A),'Espai x esquema'!$E:$E,"",0))} -> No
A21: E13_HST_A6P | B21: HST_AGD_AVA_ALUMNE_ITEM | C21: 14788 | D21: =new_212__3[[#This Row],[MBYTES]]/1024 -> 14.441406 | E21: No | F21: AM10 | H21: No són taules LOG | K21: {=IF(_xlfn.XLOOKUP(TRIM(A21),TRIM('Espai x esquema'!$A:$A),'Espai x esquema'!$E:$E,"",0)="Sí, però", "Sí", _xlfn.XLOOKUP(TRIM(A21),TRIM('Espai x esquema'!$A:$A),'Espai x esquema'!$E:$E,"",0))} -> No
A22: E13_PLD | B22: PLDTB_AP_ESPEC_PROFES | C22: 14764 | D22: 14.417969 | E22: No | F22: AM05 | G22: No en té | K22: {=IF(_xlfn.XLOOKUP(TRIM(A22),TRIM('Espai x esquema'!$A:$A),'Espai x esquema'!$E:$E,"",0)="Sí, però", "Sí", _xlfn.XLOOKUP(TRIM(A22),TRIM('Espai x esquema'!$A:$A),'Espai x esquema'!$E:$E,"",0))} -> No
A23: E13_BAE | B23: BAE_DMA_CURRICULUM | C23: 14211 | D23: =new_212__3[[#This Row],[MBYTES]]/1024 -> 13.87793 | E23: No | F23: AM10 | G23: Cal conservar, dades amb finestra de dos anys | K23: {=IF(_xlfn.XLOOKUP(TRIM(A23),TRIM('Espai x esquema'!$A:$A),'Espai x esquema'!$E:$E,"",0)="Sí, però", "Sí", _xlfn.XLOOKUP(TRIM(A23),TRIM('Espai x esquema'!$A:$A),'Espai x esquema'!$E:$E,"",0))} -> No
A24: E13_AGD | B24: OLD_HST_AGD_AVA_ALUMNE_ITEM | C24: 13944 | D24: =new_212__3[[#This Row],[MBYTES]]/1024 -> 13.617188 | E24: No | F24: AM10 | H24: No són taules LOG | K24: {=IF(_xlfn.XLOOKUP(TRIM(A24),TRIM('Espai x esquema'!$A:$A),'Espai x esquema'!$E:$E,"",0)="Sí, però", "Sí", _xlfn.XLOOKUP(TRIM(A24),TRIM('Espai x esquema'!$A:$A),'Espai x esquema'!$E:$E,"",0))} -> No
A25: SAGA_CENTRAL | B25: BO_LOG_AUTORITZACIO | C25: 13106 | D25: =new_212__3[[#This Row],[MBYTES]]/1024 -> 12.798828 | E25: Sí | F25: AM11 | G25: Politica d'esborrat anys anteriors, hi ha dades des del 2006 | H25: Procediments Oracle on desa els errors de les accions | I25: SAGA | J25: Oscar Mendez | K25: {=IF(_xlfn.XLOOKUP(TRIM(A25),TRIM('Espai x esquema'!$A:$A),'Espai x esquema'!$E:$E,"",0)="Sí, però", "Sí", _xlfn.XLOOKUP(TRIM(A25),TRIM('Espai x esquema'!$A:$A),'Espai x esquema'!$E:$E,"",0))} -> No
A26: E13_A6P | B26: HST_A6P_RESULTAT | C26: 12548 | D26: =new_212__3[[#This Row],[MBYTES]]/1024 -> 12.253906 | E26: No | F26: AM10 | H26: No són taules LOG | K26: {=IF(_xlfn.XLOOKUP(TRIM(A26),TRIM('Espai x esquema'!$A:$A),'Espai x esquema'!$E:$E,"",0)="Sí, però", "Sí", _xlfn.XLOOKUP(TRIM(A26),TRIM('Espai x esquema'!$A:$A),'Espai x esquema'!$E:$E,"",0))} -> No
A27: E13_A4S | B27: HST_A4S_RESULTAT | C27: 11088 | D27: =new_212__3[[#This Row],[MBYTES]]/1024 -> 10.828125 | E27: No | F27: AM10 | H27: No són taules LOG | K27: {=IF(_xlfn.XLOOKUP(TRIM(A27),TRIM('Espai x esquema'!$A:$A),'Espai x esquema'!$E:$E,"",0)="Sí, però", "Sí", _xlfn.XLOOKUP(TRIM(A27),TRIM('Espai x esquema'!$A:$A),'Espai x esquema'!$E:$E,"",0))} -> No
A28: E13_BAE | B28: BAE_DMA_CURRICULUM_AVALUACIO | C28: 10952 | D28: =new_212__3[[#This Row],[MBYTES]]/1024 -> 10.695312 | E28: No | F28: AM10 | G28: Cal conservar, dades amb finestra de dos anys | K28: {=IF(_xlfn.XLOOKUP(TRIM(A28),TRIM('Espai x esquema'!$A:$A),'Espai x esquema'!$E:$E,"",0)="Sí, però", "Sí", _xlfn.XLOOKUP(TRIM(A28),TRIM('Espai x esquema'!$A:$A),'Espai x esquema'!$E:$E,"",0))} -> No
A29: GEDAC | B29: LOG_GEDAC | C29: 10914 | D29: =new_212__3[[#This Row],[MBYTES]]/1024 -> 10.658203 | E29: No | F29: AM10 | G29: Cal conservar, són els logs dels darrers 15 dies | K29: {=IF(_xlfn.XLOOKUP(TRIM(A29),TRIM('Espai x esquema'!$A:$A),'Espai x esquema'!$E:$E,"",0)="Sí, però", "Sí", _xlfn.XLOOKUP(TRIM(A29),TRIM('Espai x esquema'!$A:$A),'Espai x esquema'!$E:$E,"",0))} -> No
A30: GEDAC | B30: GEDACPRE_ENVIAMENT_CORREUS | C30: 10591 | D30: =new_212__3[[#This Row],[MBYTES]]/1024 -> 10.342773 | E30: No | F30: AM10 | G30: No existeix política d'esborrat. | K30: {=IF(_xlfn.XLOOKUP(TRIM(A30),TRIM('Espai x esquema'!$A:$A),'Espai x esquema'!$E:$E,"",0)="Sí, però", "Sí", _xlfn.XLOOKUP(TRIM(A30),TRIM('Espai x esquema'!$A:$A),'Espai x esquema'!$E:$E,"",0))} -> No
A31: E13_AAC_PREINS | B31: AACTBLOG_WS | C31: 9128 | D31: =new_212__3[[#This Row],[MBYTES]]/1024 -> 8.9140625 | E31: No | F31: AM10 | G31: No existeix política d'esborrat. | K31: {=IF(_xlfn.XLOOKUP(TRIM(A31),TRIM('Espai x esquema'!$A:$A),'Espai x esquema'!$E:$E,"",0)="Sí, però", "Sí", _xlfn.XLOOKUP(TRIM(A31),TRIM('Espai x esquema'!$A:$A),'Espai x esquema'!$E:$E,"",0))} -> Sí
A32: GAVIS | B32: UTILS_TB_LOG | C32: 8501 | D32: =new_212__3[[#This Row],[MBYTES]]/1024 -> 8.3017578 | E32: No | F32: AM10 | K32: {=IF(_xlfn.XLOOKUP(TRIM(A32),TRIM('Espai x esquema'!$A:$A),'Espai x esquema'!$E:$E,"",0)="Sí, però", "Sí", _xlfn.XLOOKUP(TRIM(A32),TRIM('Espai x esquema'!$A:$A),'Espai x esquema'!$E:$E,"",0))} -> No
A33: E13_RALC | B33: UTILS_TB_LOG | C33: 8274 | D33: =new_212__3[[#This Row],[MBYTES]]/1024 -> 8.0800781 | E33: No | F33: AM10 | G33: Cal conservar, es manté el LOG de 6 mesos | K33: {=IF(_xlfn.XLOOKUP(TRIM(A33),TRIM('Espai x esquema'!$A:$A),'Espai x esquema'!$E:$E,"",0)="Sí, però", "Sí", _xlfn.XLOOKUP(TRIM(A33),TRIM('Espai x esquema'!$A:$A),'Espai x esquema'!$E:$E,"",0))} -> No
A34: E13_OFE_EDU | B34: UTILS_TB_LOG | C34: 7916 | D34: =new_212__3[[#This Row],[MBYTES]]/1024 -> 7.7304688 | E34: No | F34: AM10 | G34: No existeix política d'esborrat. | K34: {=IF(_xlfn.XLOOKUP(TRIM(A34),TRIM('Espai x esquema'!$A:$A),'Espai x esquema'!$E:$E,"",0)="Sí, però", "Sí", _xlfn.XLOOKUP(TRIM(A34),TRIM('Espai x esquema'!$A:$A),'Espai x esquema'!$E:$E,"",0))} -> No
A35: GAFADM | B35: T_LOG_ACTIVITAT | C35: 7592 | D35: 7.4140625 | E35: No | F35: AM05 | G35: No en té | K35: {=IF(_xlfn.XLOOKUP(TRIM(A35),TRIM('Espai x esquema'!$A:$A),'Espai x esquema'!$E:$E,"",0)="Sí, però", "Sí", _xlfn.XLOOKUP(TRIM(A35),TRIM('Espai x esquema'!$A:$A),'Espai x esquema'!$E:$E,"",0))} -> No
A36: E13_BAE | B36: BKBAE_DMA_CURRICULUM | C36: 7589 | D36: =new_212__3[[#This Row],[MBYTES]]/1024 -> 7.4111328 | E36: Sí | F36: AM10 | G36: Taula de backup sol·licitada en un AGIN ja resolt | I36: BAE | J36: Andrea Cánovas | K36: {=IF(_xlfn.XLOOKUP(TRIM(A36),TRIM('Espai x esquema'!$A:$A),'Espai x esquema'!$E:$E,"",0)="Sí, però", "Sí", _xlfn.XLOOKUP(TRIM(A36),TRIM('Espai x esquema'!$A:$A),'Espai x esquema'!$E:$E,"",0))} -> No
A37: E13_BAE | B37: BK3BAE_DMA_CURRICULUM | C37: 7574 | D37: =new_212__3[[#This Row],[MBYTES]]/1024 -> 7.3964844 | E37: Sí | F37: AM10 | G37: Taula de backup sol·licitada en un AGIN ja resolt | I37: BAE | J37: Andrea Cánovas | K37: {=IF(_xlfn.XLOOKUP(TRIM(A37),TRIM('Espai x esquema'!$A:$A),'Espai x esquema'!$E:$E,"",0)="Sí, però", "Sí", _xlfn.XLOOKUP(TRIM(A37),TRIM('Espai x esquema'!$A:$A),'Espai x esquema'!$E:$E,"",0))} -> No
A38: E13_BAE | B38: BK2BAE_DMA_CURRICULUM | C38: 7573 | D38: =new_212__3[[#This Row],[MBYTES]]/1024 -> 7.3955078 | E38: Sí | F38: AM10 | G38: Taula de backup sol·licitada en un AGIN ja resolt | I38: BAE | J38: Andrea Cánovas | K38: {=IF(_xlfn.XLOOKUP(TRIM(A38),TRIM('Espai x esquema'!$A:$A),'Espai x esquema'!$E:$E,"",0)="Sí, però", "Sí", _xlfn.XLOOKUP(TRIM(A38),TRIM('Espai x esquema'!$A:$A),'Espai x esquema'!$E:$E,"",0))} -> No
A39: E13_AGD | B39: OLD_HST_AGD_RESULTAT | C39: 7388 | D39: =new_212__3[[#This Row],[MBYTES]]/1024 -> 7.2148438 | E39: No | F39: AM10 | H39: No són taules LOG | K39: {=IF(_xlfn.XLOOKUP(TRIM(A39),TRIM('Espai x esquema'!$A:$A),'Espai x esquema'!$E:$E,"",0)="Sí, però", "Sí", _xlfn.XLOOKUP(TRIM(A39),TRIM('Espai x esquema'!$A:$A),'Espai x esquema'!$E:$E,"",0))} -> No
A40: E13_SIDIE | B40: EX_V_DMA_CURRICULUM | C40: 6945 | D40: =new_212__3[[#This Row],[MBYTES]]/1024 -> 6.7822266 | E40: No | F40: AM10 | K40: {=IF(_xlfn.XLOOKUP(TRIM(A40),TRIM('Espai x esquema'!$A:$A),'Espai x esquema'!$E:$E,"",0)="Sí, però", "Sí", _xlfn.XLOOKUP(TRIM(A40),TRIM('Espai x esquema'!$A:$A),'Espai x esquema'!$E:$E,"",0))} -> No
...
